Workbook
Name Beginning_Balance: -FV(Interest_Rate/12,Payment_Number-1,-Monthly_Payment,Loan_Amount)
Name Ending_Balance: -FV(Interest_Rate/12,Payment_Number,-Monthly_Payment,Loan_Amount)
Name Header_Row: ROW(#REF!)
Name Interest: -IPMT(Interest_Rate/12,Payment_Number,Number_of_Payments,Loan_Amount)
Name Interest_Rate: #REF!
Name Last_Row: IF(Values_Entered,Header_Row+Number_of_Payments,Header_Row)
Name Loan_Amount: #REF!
Name Loan_Not_Paid: IF(Payment_Number<=Number_of_Payments,1,0)
Name Loan_Start: #REF!
Name Loan_Years: #REF!
Name Monthly_Payment: -PMT(Interest_Rate/12,Number_of_Payments,Loan_Amount)
Name Number_of_Payments: #REF!
Name Payment_Date: DATE(YEAR(Loan_Start),MONTH(Loan_Start)+Payment_Number,DAY(Loan_Start))
Name Payment_Number: ROW()-Header_Row
Name Principal: -PPMT(Interest_Rate/12,Payment_Number,Number_of_Payments,Loan_Amount)
Name Total_Cost: #REF!
Name Values_Entered: IF(Loan_Amount*Interest_Rate*Loan_Years*Loan_Start>0,1,0)

Sheet DB
L2: لوحة بيانات
L3: مشروع | M3: ='SCENARIO-1 '!D2 -> ABC
B8: KPI
B87: العماله
B106: المعدات
B138: المستهلاكات
B190: توزيع التكاليف

Sheet SCENARIO-1 
C2: دراسة جدوى مالية مشروع | D2: ABC
B6: تكلفة العماله | C6: 1
B8: الوصف | C8: الراتب الأساسي | D8: بدلات | E8: مكافائات | F8: تأمينات | G8: تأمين صحي شامل | H8: ضريبة كسب عمل | I8: يونيفورم/حذاء أمان | J8: ضريبة صندوق الشهيد | K8: الاجمالي
B9: مدير | C9: =CHOOSE(C6,G.SALARY!D51,G.SALARY!G51) -> 12000 | D9: 0 | E9: 0 | F9: =F16 -> 4521.0383 | G9: 130 | H9: =CHOOSE(C6,G.SALARY!D49,G.SALARY!G49) -> 1517.5246 | I9: 0 | J9: =CHOOSE(C6,G.SALARY!D50,G.SALARY!G50) -> 7.5983837 | K9: =SUM(C9:J9) -> 18176.161 | L9: =E33*K9 -> 18176.161
B10: مشرف | C10: =CHOOSE(C6,G.SALARY!D32,G.SALARY!G32) -> 9000 | D10: 0 | E10: 0 | F10: =F17 -> 3266.6462 | G10: 130 | H10: =CHOOSE(C6,G.SALARY!D30,G.SALARY!G30) -> 766.99754 | I10: 70 | J10: =CHOOSE(C6,G.SALARY!D31,G.SALARY!G31) -> 5.4901616 | K10: =SUM(C10:J10) -> 13239.134 | L10: =E34*K10 -> 79434.803
B11: عامل | C11: =CHOOSE(C6,G.SALARY!D13,G.SALARY!G13) -> 7000 | D11: 0 | E11: 0 | F11: =F18 -> 2434.8958 | G11: 130 | H11: =CHOOSE(C6,G.SALARY!D11,G.SALARY!G11) -> 280.13393 | I11: 100 | J11: =CHOOSE(C6,G.SALARY!D12,G.SALARY!G12) -> 4.0922619 | K11: =SUM(C11:J11) -> 9949.122 | L11: =E35*K11 -> 417863.13
L12: =SUM(L9:L11) -> 515474.09
B13: حساب التأمينات
B15: الوصف | C15: الراتب التأميني | D15: نسبة الشركة 18.75% | E15: نسبة العامل 11% | F15: أجمالي التأمينات
B16: مدير | C16: =CHOOSE(C6,G.SALARY!D46,G.SALARY!G46) -> 15196.767 | D16: =C16*18.75% -> 2849.3939 | E16: =C16*11% -> 1671.6444 | F16: =SUM(D16:E16) -> 4521.0383
B17: مشرف | C17: =CHOOSE(C6,G.SALARY!D27,G.SALARY!G27) -> 10980.323 | D17: =C17*18.75% -> 2058.8106 | E17: =C17*11% -> 1207.8356 | F17: =SUM(D17:E17) -> 3266.6462
B18: عامل | C18: =CHOOSE(C6,G.SALARY!D8,G.SALARY!G8) -> 8184.5238 | D18: =C18*18.75% -> 1534.5982 | E18: =C18*11% -> 900.29762 | F18: =SUM(D18:E18) -> 2434.8958
B20: عدد العماله
D21: =CHOOSE(F21,INPUTS!E9,INPUTS!E10,INPUTS!E11,INPUTS!E12) -> اختيار1: 8 ساعات/7 أيام | F21: 1
B24: الوصف | C24: الصباحية | D24: المسائية | E24: الليلية | F24: الأجمالي
B25: مدير | C25: 1 | D25: 0 | E25: 0 | F25: =SUM(C25:E25) -> 1
B26: مشرف | C26: 2 | D26: 2 | E26: 1 | F26: =SUM(C26:E26) -> 5
B27: عامل | C27: 12 | D27: 12 | E27: 12 | F27: =SUM(C27:E27) -> 36
B29: أجمالي العماله | D29: 0.166
C30: 1
B32: الوصف | C32: العدد المطلوب | D32: تغطية الأجازات | E32: أجمالي العدد | F32: مرتبات | G32: بدلات | H32: مكافائات | I32: تأمينات | J32: تأمين صحي | K32: ضريبة كسب عمل | L32: يونيفورم | M32: صندوق الشهداء | N32: أجمالي التكلفة
B33: مدير | C33: =F25 -> 1 | D33: 0 | E33: =SUM(C33:D33) -> 1 | F33: =E33*C9 -> 12000 | G33: =$E$33*D9 -> 0 | H33: =$E$33*E9 -> 0 | I33: =$E$33*F9 -> 4521.0383 | J33: =$E$33*G9 -> 130 | K33: =$E$33*H9 -> 1517.5246 | L33: =$E$33*I9 -> 0 | M33: =$E$33*J9 -> 7.5983837 | N33: =SUM(F33:M33) -> 18176.161
B34: مشرف | C34: =F26 -> 5 | D34: =CHOOSE($C$30,C34*$D$29,0,0) -> 0.83 | E34: =C34+ROUNDUP(D34,0) -> 6 | F34: =$E$34*C10 -> 54000 | G34: =$E$34*D10 -> 0 | H34: =$E$34*E10 -> 0 | I34: =$E$34*F10 -> 19599.877 | J34: =$E$34*G10 -> 780 | K34: =$E$34*H10 -> 4601.9852 | L34: =$E$34*I10 -> 420 | M34: =$E$34*J10 -> 32.94097 | N34: =SUM(F34:M34) -> 79434.803
B35: عامل | C35: =F27 -> 36 | D35: =CHOOSE($C$30,C35*$D$29,0,C35*$D$29) -> 5.976 | E35: =C35+ROUNDUP(D35,0) -> 42 | F35: =E35*C11 -> 294000 | G35: =$E$35*D11 -> 0 | H35: =$E$35*E11 -> 0 | I35: =$E$35*F11 -> 102265.62 | J35: =$E$35*G11 -> 5460 | K35: =$E$35*H11 -> 11765.625 | L35: =$E$35*I11 -> 4200 | M35: =$E$35*J11 -> 171.875 | N35: =SUM(F35:M35) -> 417863.13
B36: الأجمالي | C36: =SUM(C33:C35) -> 42 | D36: =SUM(D34:D35) -> 6.806 | E36: =SUM(E33:E35) -> 49 | F36: =SUM(F33:F35) -> 360000 | G36: =SUM(G33:G35) -> 0 | H36: =SUM(H33:H35) -> 0 | I36: =SUM(I33:I35) -> 126386.54 | J36: =SUM(J33:J35) -> 6370 | K36: =SUM(K33:K35) -> 17885.135 | L36: =SUM(L33:L35) -> 4620 | ... N36: =SUM(N33:N35) -> 515474.09
N37: =$N$36-$L$12 -> 0
B39: تكلفة مورد الأفراد | C39: 1
B41: الورديات | C41: عدد العمال | D41: عدد النقلات | E41: تكلفة النقلة | F41: التكلفة اليومية | G41: تكلفة شهرية | H41: تكلفة الفرد
B42: صباحية | C42: 0 | D42: 1 | E42: 1600 | F42: =E42*D42 -> 1600 | G42: =F42*CHOOSE($C$39,INPUTS!$D$19,INPUTS!$D$20) -> 49600 | H42: =G45/C36 -> 3542.8571
B43: مسائية | C43: 0 | D43: 1 | E43: 1600 | F43: =E43*D43 -> 1600 | G43: =F43*CHOOSE($C$39,INPUTS!$D$19,INPUTS!$D$20) -> 49600
B44: ليلية | C44: 0 | D44: 1 | E44: 1600 | F44: =E44*D44 -> 1600 | G44: =F44*CHOOSE($C$39,INPUTS!$D$19,INPUTS!$D$20) -> 49600
B45: الأجمالي | C45: =SUM(C42:C44) -> 0 | D45: =SUM(D42:D44) -> 3 | E45: =E42 -> 1600 | F45: =SUM(F42:F44) -> 4800 | G45: =SUM(G42:G44) -> 148800
F46: =F45*31 -> 148800
B48: وجبات
B50: الوصف | C50: عدد العمال | D50: السعر | E50: أجمالي القيمة | F50: تكلفة الفرد
B51: وجبة | C51: 0 | D51: 50 | E51: =D51*C51 -> 0 | F51: =E51/C35 -> 0
B54: سكن عماله
B56: الوصف | C56: العدد | D56: الايجار | E56: أجمالي القيمة | F56: تكلفة الفرد
B57: شقة | C57: 0 | D57: 3000 | E57: =D57*C57 -> 0 | F57: =E57/C35 -> 0
B60: الماكينات والمعدات
...

Sheet F.O
B2: عرض سعر | C2: ='SCENARIO-1 '!D2 -> ABC
B4: أجمالي سعر بيع غير مفصل
B6: الوصف | C6: التكلفة المتغيرة | D6: التكلفة الثابتة | E6: أجمالي تكلفة الفرد | F6: سعر بيع الفرد | G6: أجمالي سعر البيع
B7: مدير | C7: =IFERROR('SCENARIO-1 '!N33/'SCENARIO-1 '!C33,0) -> 18176.161 | D7: ='B.E.P'!$C$34 -> 7348.0939 | E7: =D7+C7 -> 25524.255 | F7: =E7*(1+'SCENARIO-1 '!$C$200) -> 28804.428 | G7: =F7*'SCENARIO-1 '!C33 -> 28804.428
B8: المشرف | C8: =IFERROR('SCENARIO-1 '!N34/'SCENARIO-1 '!C34,0) -> 15886.961 | D8: ='B.E.P'!$C$34 -> 7348.0939 | E8: =D8+C8 -> 23235.055 | F8: =E8*(1+'SCENARIO-1 '!$C$200) -> 26221.038 | G8: =F8*'SCENARIO-1 '!C34 -> 131105.19
B9: العامل | C9: =IFERROR('SCENARIO-1 '!N35/'SCENARIO-1 '!C35+'SCENARIO-1 '!$F$51,0) -> 11607.309 | D9: ='B.E.P'!$C$34 -> 7348.0939 | E9: =D9+C9 -> 18955.403 | F9: =E9*(1+'SCENARIO-1 '!$C$200) -> 21391.4 | G9: =F9*'SCENARIO-1 '!C35 -> 770090.38
B10: الأجمالي | G10: =SUMIF(G7:G9,">0") -> 930000
B12: سعر بيع عماله
B14: الوصف | C14: التكلفة المتغيرة | D14: MARK UP | E14: سعر بيع الفرد | F14: أجمالي سعر البيع
B15: مدير | C15: =C7 -> 18176.161 | D15: =D23 -> 1.1888873 | E15: =C15*D15 -> 21609.407 | F15: =E15*'SCENARIO-1 '!C33 -> 21609.407
B16: المشرف | C16: =C8 -> 15886.961 | D16: =D24 -> 1.1888873 | E16: =C16*D16 -> 18887.806 | F16: =E16*'SCENARIO-1 '!C34 -> 94439.029
B17: العامل | C17: =C9 -> 11607.309 | D17: =D25 -> 1.1888873 | E17: =C17*D17 -> 13799.782 | F17: =E17*'SCENARIO-1 '!C35 -> 496792.16
B18: الأجمالي | F18: =SUMIF(F15:F17,">0") -> 612840.6
B21: أجمالي سعر بيع مفصل
D22: MARK UP | E22: السعر
B23: تكلفة العماله | C23: ='SCENARIO-1 '!C178 -> 515474.09 | D23: =1+'SCENARIO-1 '!$C$199 -> 1.1888873 | E23: =C23*D23 -> 612840.6
B24: مورد نقل عماله | C24: ='SCENARIO-1 '!C179 -> 148800 | D24: =1+'SCENARIO-1 '!$C$199 -> 1.1888873 | E24: =C24*D24 -> 176906.43 | F24: =SUM(E23:E24) -> 789747.03
B25: سكن عمال | C25: ='SCENARIO-1 '!C180 -> 0 | D25: =1+'SCENARIO-1 '!$C$199 -> 1.1888873 | E25: =C25*D25 -> 0
B26: أهلاكات ماكينات ومعدات وصيانة | C26: ='SCENARIO-1 '!C181+'SCENARIO-1 '!C183 -> 66311.667 | D26: =1+'SCENARIO-1 '!$C$199 -> 1.1888873 | E26: =C26*D26 -> 78837.099
B27: تأجير هاي بريشر | C27: ='SCENARIO-1 '!C182 -> 0 | D27: =1+'SCENARIO-1 '!$C$199 -> 1.1888873 | E27: =C27*D27 -> 0
B28: أدوات ومستهلاكات | C28: ='SCENARIO-1 '!C184 -> 16477.156 | D28: =1+'SCENARIO-1 '!$C$199 -> 1.1888873 | E28: =C28*D28 -> 19589.482
B29: مصاريف أداري وعمومية | C29: ='SCENARIO-1 '!C190 -> 35181.121 | D29: =1+'SCENARIO-1 '!$C$199 -> 1.1888873 | E29: =C29*D29 -> 41826.388
B30: الأجمالي | E30: =SUM(E23:E29) -> 930000

Sheet O.H1
C2: حساب المصاريف الغير مباشرة
C3: أدارية وعمومية وتشغيل
C4: حسب نسبة الربح
B6: العقود الحالية
B8: الفرع | C8: القيمة | D8: النسبة | E8: المصاريف الغير مباشرة | F8: قيمة الفرع
B9: كارفور المعادي | C9: 728200 | D9: =C9/C$33 -> 0.06678108 | E9: 412500 | F9: =E9*D9 -> 27547.196
B10: كارفور فيتالي | C10: 63800 | D10: =C10/C$33 -> 0.0058509104 | E10: 412500 | F10: =E10*D10 -> 2413.5005
B11: كارفور C3 NEW CAIRO | C11: 155100 | D11: =C11/C$33 -> 0.014223765 | E11: 412500 | F11: =E11*D11 -> 5867.303
B12: كارفور الماظه | C12: 573100 | D12: =C12/C$33 -> 0.052557316 | E12: 412500 | F12: =E12*D12 -> 21679.893
B13: كارفور كايرو | C13: 630300 | D13: =C13/C$33 -> 0.057802959 | E13: 412500 | F13: =E13*D13 -> 23843.721
B14: لولو | C14: 573319 | D14: =C14/C$33 -> 0.052577399 | E14: 412500 | F14: =E14*D14 -> 21688.177
B15: لولو بارك مول | C15: 457209 | D15: =C15/C$33 -> 0.041929293 | E15: 412500 | F15: =E15*D15 -> 17295.833
B16: لولو التجمع | C16: 462054 | D16: =C16/C$33 -> 0.042373613 | E16: 412500 | F16: =E16*D16 -> 17479.116
B17: لولو العبور | C17: 462054 | D17: =C17/C$33 -> 0.042373613 | E17: 412500 | F17: =E17*D17 -> 17479.116
B18: كارفور مول مصر | C18: 563200 | D18: =C18/C$33 -> 0.051649416 | E18: 412500 | F18: =E18*D18 -> 21305.384
B19: كارفور العبور | C19: 490600 | D19: =C19/C$33 -> 0.044991483 | E19: 412500 | F19: =E19*D19 -> 18558.987
B20: كارفور داندي | C20: 437800 | D20: =C20/C$33 -> 0.04014935 | E20: 412500 | F20: =E20*D20 -> 16561.607
... B31: الحكمة بدر | C31: 82975 | D31: =C31/C$33 -> 0.0076093932 | E31: 412500 | F31: =E31*D31 -> 3138.8747
B32: فرع الدراسة | C32: ='SCENARIO-1 '!C176 -> 930000 | D32: =C32/C$33 -> 0.085287565 | E32: 412500 | F32: =E32*D32 -> 35181.121
B33: الأجمالي | C33: =SUM(C9:C32) -> 10904286 | D33: =C33/C$33 -> 1 | E33: 412500 | F33: =SUM(F9:F32) -> 412500
B35: Q1 | C35: =_xlfn.QUARTILE.INC($C$9:$C$32,1) -> 156750
B36: Q2 | C36: =_xlfn.QUARTILE.INC($C$9:$C$32,2) -> 459631.5
B37: Q3 | C37: =_xlfn.QUARTILE.INC($C$9:$C$32,3) -> 565675
B38: Q4 | C38: =_xlfn.QUARTILE.INC($C$9:$C$32,4) -> 2307500
B39: IQR | C39: =C37-C35 -> 408925
B40: FENCE AT +1.5 IQR | C40: =C39*1.5+C37 -> 1179062.5
B42: المتوسط | C42: =AVERAGE(D9:D31) -> 0.039770106
B43: الوسط | C43: =MEDIAN(D9:D31) -> 0.041929293
B45: قيم العقود وعدد الساعات
B47: الفرع | C47: القيمة | D47: عدد ساعات العمل في الشهر
B48: كارفور المعادي | C48: =VLOOKUP(B48,$B$8:$C$31,2,FALSE) -> 728200 | D48: =VLOOKUP(B48,O.H2!$B$8:$E$32,4,FALSE) -> 11280
B49: كارفور فيتالي | C49: =VLOOKUP(B49,$B$8:$C$31,2,FALSE) -> 63800 | D49: =VLOOKUP(B49,O.H2!$B$8:$E$32,4,FALSE) -> 1800
B50: كارفور C3 NEW CAIRO | C50: =VLOOKUP(B50,$B$8:$C$31,2,FALSE) -> 155100 | D50: =VLOOKUP(B50,O.H2!$B$8:$E$32,4,FALSE) -> 3600
B51: كارفور الماظه | C51: =VLOOKUP(B51,$B$8:$C$31,2,FALSE) -> 573100 | D51: =VLOOKUP(B51,O.H2!$B$8:$E$32,4,FALSE) -> 8400
B52: كارفور كايرو | C52: =VLOOKUP(B52,$B$8:$C$31,2,FALSE) -> 630300 | D52: =VLOOKUP(B52,O.H2!$B$8:$E$32,4,FALSE) -> 8400
B53: لولو | C53: =VLOOKUP(B53,$B$8:$C$31,2,FALSE) -> 573319 | D53: =VLOOKUP(B53,O.H2!$B$8:$E$32,4,FALSE) -> 12000
B54: لولو بارك مول | C54: =VLOOKUP(B54,$B$8:$C$31,2,FALSE) -> 457209 | D54: =VLOOKUP(B54,O.H2!$B$8:$E$32,4,FALSE) -> 9600
B55: لولو التجمع | C55: =VLOOKUP(B55,$B$8:$C$31,2,FALSE) -> 462054 | D55: =VLOOKUP(B55,O.H2!$B$8:$E$32,4,FALSE) -> 11280
B56: لولو العبور | C56: =VLOOKUP(B56,$B$8:$C$31,2,FALSE) -> 462054 | D56: =VLOOKUP(B56,O.H2!$B$8:$E$32,4,FALSE) -> 11280
B57: كارفور مول مصر | C57: =VLOOKUP(B57,$B$8:$C$31,2,FALSE) -> 563200 | D57: =VLOOKUP(B57,O.H2!$B$8:$E$32,4,FALSE) -> 8400
...

Sheet O.H2
C2: حساب المصاريف الغير مباشرة
C3: أدارية وعمومية وتشغيل
C4: حسب عدد ساعات العماله
B6: العقود الحالية
B8: الفرع | C8: عدد العماله | D8: عدد ساعات العمل في الشهر | E8: أجمالي ساعات العمل | F8: المصاريف الغير مباشرة | G8: قيمة الساعة | H8: قيمة الفرع | I8: النسبة
B9: فرع الدراسة | C9: ='SCENARIO-1 '!C35 -> 36 | D9: =CHOOSE('SCENARIO-1 '!F21,INPUTS!D9,INPUTS!D10,INPUTS!D11,INPUTS!D12) -> 240 | E9: =D9*C9 -> 8640 | F9: 412500 | G9: =F9/E$33 -> 2.312116 | H9: =G9*E9 -> 19976.683 | I9: =H9/H$33 -> 0.048428322
B10: كارفور فيتالي | C10: 5 | D10: =12*30 -> 360 | E10: =D10*C10 -> 1800 | F10: 412500 | G10: =F10/E$33 -> 2.312116 | H10: =G10*E10 -> 4161.8089 | I10: =H10/H$33 -> 0.010089234
B11: كارفور C3 NEW CAIRO | C11: 10 | D11: =12*30 -> 360 | E11: =D11*C11 -> 3600 | F11: 412500 | G11: =F11/E$33 -> 2.312116 | H11: =G11*E11 -> 8323.6178 | I11: =H11/H$33 -> 0.020178467
B12: الحكمة بدر | C12: 10 | D12: =8*26 -> 208 | E12: =D12*C12 -> 2080 | F12: 412500 | G12: =F12/E$33 -> 2.312116 | H12: =G12*E12 -> 4809.2014 | I12: =H12/H$33 -> 0.01165867
B13: كارفور مدينتي | C13: 10 | D13: =8*30 -> 240 | E13: =D13*C13 -> 2400 | F13: 412500 | G13: =F13/E$33 -> 2.312116 | H13: =G13*E13 -> 5549.0785 | I13: =H13/H$33 -> 0.013452312
B14: كارفور السلام | C14: 10 | D14: =8*30 -> 240 | E14: =D14*C14 -> 2400 | F14: 412500 | G14: =F14/E$33 -> 2.312116 | H14: =G14*E14 -> 5549.0785 | I14: =H14/H$33 -> 0.013452312
B15: ليك تاون | C15: 125 | D15: =8*30 -> 240 | E15: =D15*C15 -> 30000 | F15: 412500 | G15: =F15/E$33 -> 2.312116 | H15: =G15*E15 -> 69363.481 | I15: =H15/H$33 -> 0.16815389
B16: الحكمة أكتوبر | C16: 21 | D16: =8*26 -> 208 | E16: =D16*C16 -> 4368 | F16: 412500 | G16: =F16/E$33 -> 2.312116 | H16: =G16*E16 -> 10099.323 | I16: =H16/H$33 -> 0.024483207
B17: كارفور تاج سيتي | C17: 35 | D17: =8*30 -> 240 | E17: =D17*C17 -> 8400 | F17: 412500 | G17: =F17/E$33 -> 2.312116 | H17: =G17*E17 -> 19421.775 | I17: =H17/H$33 -> 0.04708309
B18: كارفور كليوبترا | C18: 35 | D18: =8*30 -> 240 | E18: =D18*C18 -> 8400 | F18: 412500 | G18: =F18/E$33 -> 2.312116 | H18: =G18*E18 -> 19421.775 | I18: =H18/H$33 -> 0.04708309
B19: كارفور العبور صايلو | C19: 0 | D19: =8*30 -> 240 | E19: =D19*C19 -> 0 | F19: 412500 | G19: =F19/E$33 -> 2.312116 | H19: =G19*E19 -> 0 | I19: =H19/H$33 -> 0
B20: كارفور 15 مايو | C20: 21 | D20: =8*30 -> 240 | E20: =D20*C20 -> 5040 | F20: 412500 | G20: =F20/E$33 -> 2.312116 | H20: =G20*E20 -> 11653.065 | I20: =H20/H$33 -> 0.028249854
B21: كارفور 10 رمضان | C21: 0 | D21: =8*30 -> 240 | E21: =D21*C21 -> 0 | F21: 412500 | G21: =F21/E$33 -> 2.312116 | H21: =G21*E21 -> 0 | I21: =H21/H$33 -> 0
B22: كارفور الواحات | C22: 21 | D22: =8*30 -> 240 | E22: =D22*C22 -> 5040 | F22: 412500 | G22: =F22/E$33 -> 2.312116 | H22: =G22*E22 -> 11653.065 | I22: =H22/H$33 -> 0.028249854
B23: كارفور داندي | C23: 30 | D23: =8*30 -> 240 | E23: =D23*C23 -> 7200 | F23: 412500 | G23: =F23/E$33 -> 2.312116 | H23: =G23*E23 -> 16647.236 | I23: =H23/H$33 -> 0.040356935
B24: كارفور الماظه | C24: 35 | D24: =8*30 -> 240 | E24: =D24*C24 -> 8400 | F24: 412500 | G24: =F24/E$33 -> 2.312116 | H24: =G24*E24 -> 19421.775 | I24: =H24/H$33 -> 0.04708309
B25: كارفور كايرو | C25: 35 | D25: =8*30 -> 240 | E25: =D25*C25 -> 8400 | F25: 412500 | G25: =F25/E$33 -> 2.312116 | H25: =G25*E25 -> 19421.775 | I25: =H25/H$33 -> 0.04708309
B26: كارفور مول مصر | C26: 35 | D26: =8*30 -> 240 | E26: =D26*C26 -> 8400 | F26: 412500 | G26: =F26/E$33 -> 2.312116 | H26: =G26*E26 -> 19421.775 | I26: =H26/H$33 -> 0.04708309
B27: كارفور العبور | C27: 35 | D27: =8*30 -> 240 | E27: =D27*C27 -> 8400 | F27: 412500 | G27: =F27/E$33 -> 2.312116 | H27: =G27*E27 -> 19421.775 | I27: =H27/H$33 -> 0.04708309
B28: كارفور المعادي | C28: 47 | D28: =8*30 -> 240 | E28: =D28*C28 -> 11280 | F28: 412500 | G28: =F28/E$33 -> 2.312116 | H28: =G28*E28 -> 26080.669 | I28: =H28/H$33 -> 0.063225864
... B32: لولو | C32: 50 | D32: =8*30 -> 240 | E32: =D32*C32 -> 12000 | F32: 412500 | G32: =F32/E$33 -> 2.312116 | H32: =G32*E32 -> 27745.393 | I32: =H32/H$33 -> 0.067261558
B33: الأجمالي | C33: =SUM(C9:C32) -> 740 | D33: =SUM(D9:D32) -> 5936 | E33: =SUM(E9:E32) -> 178408 | F33: 412500 | G33: =F33/E$33 -> 2.312116 | H33: =SUM(H9:H32) -> 412500 | I33: =SUM(I9:I32) -> 1
B35: عدد العماله
B36: Q1 | C36: =QUARTILE(C9:C32,1) -> 10
B37: Q2 | C37: =QUARTILE(C9:C32,2) -> 35
B38: Q3 | C38: =QUARTILE(C9:C32,3) -> 37
B39: Q4 | C39: =QUARTILE(C9:C32,4) -> 125
B40: IQR | C40: =C38-C36 -> 27
B41: FENCE AT 1.5 IQR | C41: =C40*1.5+C38 -> 77.5
B43: ساعات العمل
B44: Q1 | C44: =QUARTILE(E9:E32,1) -> 3300
B45: Q2 | C45: =QUARTILE(E9:E32,2) -> 8400
B46: Q3 | C46: =QUARTILE(E9:E32,3) -> 8880
B47: Q4 | C47: =QUARTILE(E9:E32,4) -> 30000
B48: IQR | C48: =C46-C44 -> 5580
...

Sheet P&L
B2: قائمة الدخل
B3: مشروع | C3: ='SCENARIO-1 '!D2 -> ABC
E4: Insert | F4: Insert
E5: زيادة العقد | F5: التضخم
B6: معدل تصخم 15% من السنة الثانية | C6: INFLATION RATE | E6: 0.1 | F6: 0.15
B7: IN EGP | C7: 1 | D7: 2 | E7: 3 | F7: 4 | G7: 5 | H7: 6 | I7: 7 | J7: 8 | K7: 9
B8: أجمالي الدخل | C8: ='SCENARIO-1 '!C176*12 -> 11160000 | D8: =C8*(1+E6) -> 12276000 | E8: =D8*(1+E6) -> 13503600
B9: أجمالي المصاريف | C9: =-('SCENARIO-1 '!C191-'SCENARIO-1 '!C181)*12 -> -8663528.4 | D9: =C9*(1+F6) -> -9963057.7 | E9: =D9*(1+F6) -> -11457516
B10: الدخل قبل الضريبة والفوائد والأهلاك | C10: =C8+C9 -> 2496471.6 | D10: =D8+D9 -> 2312942.3 | E10: =E8+E9 -> 2046083.7
B11: الأهلاك | C11: =-'SCENARIO-1 '!$C$181*12 -> -723400 | D11: =-'SCENARIO-1 '!$C$181*12 -> -723400 | E11: =-'SCENARIO-1 '!$C$181*12 -> -723400
B12: الدخل قبل الضريبة والفوائد | C12: =C10+C11 -> 1773071.6 | D12: =D10+D11 -> 1589542.3 | E12: =E10+E11 -> 1322683.7 | F12: =SUM(F8:F11) -> 0 | G12: =SUM(G8:G11) -> 0 | H12: =SUM(H8:H11) -> 0 | I12: =SUM(I8:I11) -> 0 | J12: =SUM(J8:J11) -> 0 | K12: =SUM(K8:K11) -> 0
B13: الفوائد | C13: ='C.F'!D12 -> 0 | D13: ='C.F'!E12 -> 0 | E13: ='C.F'!F12 -> 0
B14: الدخل قبل الضريبة | C14: =C12+C13 -> 1773071.6 | D14: =D12+D13 -> 1589542.3 | E14: =E12+E13 -> 1322683.7 | F14: =SUM(F12:F13) -> 0 | G14: =SUM(G12:G13) -> 0 | H14: =SUM(H12:H13) -> 0 | I14: =SUM(I12:I13) -> 0 | J14: =SUM(J12:J13) -> 0 | K14: =SUM(K12:K13) -> 0
B15: الضرائب | C15: =-(C8*20%)*(22.5%) -> -502200 | D15: =-(D8*20%)*(22.5%) -> -552420 | E15: =-(E8*20%)*(22.5%) -> -607662
B16: صافي الدخل | C16: =C14+C15 -> 1270871.6 | D16: =D14+D15 -> 1037122.3 | E16: =E14+E15 -> 715021.7 | F16: =F14+F15 -> 0 | G16: =G14+G15 -> 0 | H16: =H14+H15 -> 0 | I16: =I14+I15 -> 0 | J16: =J14+J15 -> 0 | K16: =K14+K15 -> 0
B17: ضريبة خصم من المنبع 3% | C17: =C8*3% -> 334800 | D17: =D8*3% -> 368280 | E17: =E8*3% -> 405108 | F17: =F8*3% -> 0 | G17: =G8*3% -> 0 | H17: =H8*3% -> 0 | I17: =I8*3% -> 0 | J17: =J8*3% -> 0 | K17: =K8*3% -> 0
B18: صافي المبلغ المسدد للضرائب | C18: =C15+C17 -> -167400 | D18: =D15+D17 -> -184140 | E18: =E15+E17 -> -202554 | F18: =F15-F17 -> 0 | G18: =G15-G17 -> 0 | H18: =H15-H17 -> 0 | I18: =I15-I17 -> 0 | J18: =J15-J17 -> 0 | K18: =K15-K17 -> 0
B19: صافي الدخل المعدل | C19: =C16-C13 -> 1270871.6 | D19: =D16-D13 -> 1037122.3 | E19: =E16-E13 -> 715021.7 | F19: =F16+F13 -> 0 | G19: =G16+G13 -> 0 | H19: =H16+H13 -> 0 | I19: =I16+I13 -> 0 | J19: =J16+J13 -> 0 | K19: =K16+K13 -> 0
B20: تكلفة الفرصة البديلة لرأس المال | C20: =('D.C.F'!$C$7*'D.C.F'!D9) -> -992866.5 | D20: =(('C.F'!$C$8-'P&L'!D11)-'C.F'!C24)*'D.C.F'!E9 -> -775942.31 | E20: =(('C.F'!$C$8-'P&L'!E11-D11)-'C.F'!D24)*'D.C.F'!F9 -> -440817.75 | F20: =('D.C.F'!$C$7*'D.C.F'!O3) -> 0 | G20: =('D.C.F'!$C$7*'D.C.F'!P3) -> 0 | H20: =('D.C.F'!$C$7*'D.C.F'!Q3) -> 0 | I20: =('D.C.F'!$C$7*'D.C.F'!R3) -> 0 | J20: =('D.C.F'!$C$7*'D.C.F'!S3) -> 0 | K20: =('D.C.F'!$C$7*'D.C.F'!T3) -> 0
B21: القيمة الاقتصادية المضافة | C21: =C19+C20 -> 278005.1 | D21: =D19+D20 -> 261180.04 | E21: =E19+E20 -> 274203.95 | F21: =F19+F20 -> 0 | G21: =G19+G20 -> 0 | H21: =H19+H20 -> 0 | I21: =I19+I20 -> 0 | J21: =J19+J20 -> 0 | K21: =K19+K20 -> 0
B22: العائد على الاستثمار بالقيمة الاقتصادية المضافة | C22: =IFERROR(-(C21/'D.C.F'!$C$7),0) -> 0.12810114 | D22: =IFERROR(-(D21/(('C.F'!$C$8-'P&L'!D11)-'C.F'!C24)),0) -> 0.15399324 | E22: =IFERROR(-(E21/(('C.F'!$C$8-'P&L'!E11-D11)-'C.F'!D24)),0) -> 0.28458088
B28: رسم بياني
B30: العام | C30: 1 | D30: 2 | E30: 3
B31: أجمالي الدخل | C31: =C8 -> 11160000 | D31: =D8 -> 12276000 | E31: =E8 -> 13503600
B32: أجمالي المصاريف | C32: =-(C9+C11+C15) -> 9889128.4 | D32: =-(D9+D11+D15) -> 11238878 | E32: =-(E9+E11+E15) -> 12788578
B33: صافي الدخل | C33: =C31-C32 -> 1270871.6 | D33: =D31-D32 -> 1037122.3 | E33: =E31-E32 -> 715021.7
B34: القيمة الاقتصادية المضافة | C34: =C21 -> 278005.1 | D34: =D21 -> 261180.04 | E34: =E21 -> 274203.95

Sheet C.F
B2: تدفقات نقدية
B3: مشروع | C3: ='SCENARIO-1 '!D2 -> ABC
B5: IN EGP | C5: 0 | D5: 1 | E5: 2 | F5: 3
B6: الدخل قبل الفوائد والضريبة والاهلاك | D6: ='P&L'!C10 -> 2496471.6 | E6: ='P&L'!D10 -> 2312942.3 | F6: ='P&L'!E10 -> 2046083.7 | G6: ='P&L'!F10 -> 0 | H6: ='P&L'!G10 -> 0 | I6: ='P&L'!H10 -> 0 | J6: ='P&L'!I10 -> 0 | K6: ='P&L'!J10 -> 0 | ... M6: ='P&L'!L10 -> 0
B7: ضرائب | D7: ='P&L'!C15 -> -502200 | E7: ='P&L'!D15 -> -552420 | F7: ='P&L'!E15 -> -607662 | G7: ='P&L'!F15 -> 0 | H7: ='P&L'!G15 -> 0 | I7: ='P&L'!H15 -> 0 | J7: ='P&L'!I15 -> 0 | K7: ='P&L'!J15 -> 0 | ... M7: ='P&L'!L15 -> 0
B8: مصروفات رأسمالية | C8: =-'SCENARIO-1 '!H92 -> -2170200 | D8: 0 | E8: 0 | F8: 0
B9: التغير في رأس المال العامل | D9: =C25 -> 249248.75 | E9: =D25 -> -9112.6869 | F9: =E25 -> -15129.59
B10: تدفق نقدي من التشغيل | D10: =D6+D7-D8-D9 -> 1745022.9 | E10: =E6+E7-E8-E9 -> 1769635 | F10: =F6+F7-F8-F9 -> 1453551.3 | G10: =G6+G7-G8-G9 -> 0 | H10: =H6+H7-H8-H9 -> 0 | I10: =I6+I7-I8-I9 -> 0 | J10: =J6+J7-J8-J9 -> 0 | K10: =K6+K7-K8-K9 -> 0 | ... M10: =M6+M7-M8-M9 -> 0
B11: أقساط قروض | D11: =-SUM(LOANS!F14:F25) -> 0 | E11: =-SUM(LOANS!F26:F37) -> 0 | F11: =-SUM(LOANS!F38:F49) -> 0
B12: فوائد | D12: =-SUM(LOANS!E14:E25) -> 0 | E12: =-SUM(LOANS!E26:E37) -> 0 | F12: =-SUM(LOANS!E38:E49) -> 0
B13: التدفق النقدي للمشروع | C13: =SUM(C10:C12) -> 0 | D13: =SUM(D10:D12) -> 1745022.9 | E13: =SUM(E10:E12) -> 1769635 | F13: =SUM(F10:F12) -> 1453551.3 | G13: =SUM(G10:G12) -> 0 | H13: =SUM(H10:H12) -> 0 | I13: =SUM(I10:I12) -> 0 | J13: =SUM(J10:J12) -> 0 | ... M13: =SUM(M10:M12) -> 0
B17: التغير في رأس المال العامل
C19: 1 | D19: 2 | E19: 3
B20: الايراد | C20: ='SCENARIO-1 '!C176 -> 930000 | D20: =C20*(1+'P&L'!E6) -> 1023000 | E20: =D20*(1+'P&L'!E6) -> 1125300
B21: الرواتب | C21: ='SCENARIO-1 '!C178 -> 515474.09 | D21: =C21*(1+'P&L'!F$6) -> 592795.2 | E21: =D21*(1+'P&L'!F$6) -> 681714.48
B22: المورد | C22: ='SCENARIO-1 '!C179 -> 148800 | D22: =C22*(1+'P&L'!F$6) -> 171120 | E22: =D22*(1+'P&L'!F$6) -> 196788
B23: المستهلاكات | C23: ='SCENARIO-1 '!C184 -> 16477.156 | D23: =C23*(1+'P&L'!F$6) -> 18948.73 | E23: =D23*(1+'P&L'!F$6) -> 21791.039
B24: رأس المال العامل | C24: =C20-C21-C22-C23 -> 249248.75 | D24: =D20-D21-D22-D23 -> 240136.07 | E24: =E20-E21-E22-E23 -> 225006.48
B25: التغير في رأس المال العامل | C25: =C24 -> 249248.75 | D25: =D24-C24 -> -9112.6869 | E25: =E24-D24 -> -15129.59

Sheet D.C.F
B2: التدفق المالي المخصوم | L2: 1 | M2: 2 | N2: 3
B3: مشروع | C3: ='SCENARIO-1 '!D2 -> ABC | K3: RISK FREE RATE | L3: 0.2484 | M3: 0.2 | N3: 0.15
B4: EGYPT INDICATORS
B6: IN EGP | C6: 0 | D6: =IF('C.F'!D5=0,"",'C.F'!D5) -> 1 | E6: =IF('C.F'!E5=0,"",'C.F'!E5) -> 2 | F6: =IF('C.F'!F5=0,"",'C.F'!F5) -> 3 | G6: =IF('C.F'!G5=0,"",'C.F'!G5) | H6: =IF('C.F'!H5=0,"",'C.F'!H5) | I6: =IF('C.F'!I5=0,"",'C.F'!I5) | J6: =IF('C.F'!J5=0,"",'C.F'!J5) | K6: =IF('C.F'!K5=0,"",'C.F'!K5) | ... M6: =IF('C.F'!M5=0,"",'C.F'!M5) | N6: القيمة التخريدية
B7: صافي التدفق النقدي | C7: ='C.F'!C8 -> -2170200 | D7: ='C.F'!D10 -> 1745022.9 | E7: ='C.F'!E10 -> 1769635 | F7: ='C.F'!F10+N7 -> 2104611.3 | G7: 0 | H7: ='C.F'!H13 -> 0 | I7: ='C.F'!I13 -> 0 | J7: ='C.F'!J13 -> 0 | K7: ='C.F'!K13 -> 0 | L7: ='C.F'!L13 -> 0 | M7: ='C.F'!M13 -> 0 | N7: ='SCENARIO-1 '!$H$92*30% -> 651060
D8: WACC
B9: معدل الخصم | D9: =WACC!$C$24 -> 0.4575 | E9: =WACC!$C$24 -> 0.4575 | F9: =WACC!$C$24 -> 0.4575
B10: التدفق المالي المخصوم | C10: =C7/(1+C9)^C6 -> -2170200 | D10: =IFERROR(D7/(1+D9)^D6,0) -> 1197271.3 | E10: =IFERROR(E7/(1+E9)^E6,0) -> 833041.39 | F10: =IFERROR(F7/(1+F9)^F6,0) -> 679745.29 | G10: =IFERROR(G7/(1+G9)^G6,0) -> 0 | H10: =IFERROR(H7/(1+H9)^H6,0) -> 0 | I10: =IFERROR(I7/(1+I9)^I6,0) -> 0 | J10: =IFERROR(J7/(1+J9)^J6,0) -> 0 | K10: =IFERROR(K7/(1+K9)^K6,0) -> 0 | ... M10: =IFERROR(M7/(1+M9)^M6,0) -> 0
B11: القيمة الحالية للقيمة التخريدية | M11: =N7/(1+F9)^F6 -> 210278.72
B12: التدفق المالي المخصوم بالقيمة التخريدية | C12: =SUM(C10:C11) -> -2170200 | D12: =SUM(D10:D11) -> 1197271.3 | E12: =SUM(E10:E11) -> 833041.39 | F12: =SUM(F10:F11) -> 679745.29 | G12: =SUM(G10:G11) -> 0 | H12: =SUM(H10:H11) -> 0 | I12: =SUM(I10:I11) -> 0 | J12: =SUM(J10:J11) -> 0 | ... M12: =SUM(M10:M11) -> 210278.72
B14: صافي التدفق المالي المخصوم-NPV | C14: =SUM(C12:F12) -> 539857.93
B16: معدل العائد الداخلي-IRR | C16: =IFERROR(IRR(C7:F7),0) -> 0.65259525
B18: معدل الربح-PI | C18: =IFERROR(SUM(D12:F12)/C7*-1,0) -> 1.2487595
B23: =$C$10 -> -2170200 | C23: =D12 -> 1197271.3 | D23: =C23+B23 -> -972928.75
B24: =$C$10 -> -2170200 | C24: =E12 -> 833041.39 | D24: =IF(D23<=0,D23+C24,C24) -> -139887.36
B25: =$C$10 -> -2170200 | C25: =F12 -> 679745.29 | D25: =IF(D24<=0,D24+C25,C25) -> 539857.93
B28: استرداد رأس المال
B29: year 1 | C29: =B23 -> -2170200 | D29: =D23 -> -972928.75
B30: year 2 | C30: =B24 -> -2170200 | D30: =D24 -> -139887.36
B31: year 3 | C31: =B25 -> -2170200 | D31: =D25 -> 539857.93

Sheet M.C
B2: Monte Carlo Simulation
F25: Insert | L25: NPV | M25: IRR
B26: CF | C26: =AVERAGEIF('D.C.F'!D7:M7,"<>0") -> 1873089.7 | D26: SDTV | E26: =C26*F26 -> 337156.15 | F26: 0.18 | K26: MEAN | L26: =AVERAGE(L33:L1032) -> 597047.82 | M26: =AVERAGE(M33:M1032) -> 0.6801547
B27: YRS | C27: {=SUMPRODUCT(--('D.C.F'!D6:M6<>""))} -> 3 | K27: MEDIAN | L27: =MEDIAN(L33:L1032) -> 591607.37 | M27: =MEDIAN(M33:M1032) -> 0.67664966
B28: WACC | C28: =AVERAGE('D.C.F'!D9:F9) -> 0.4575 | K28: MAX | L28: =MAX(L33:L1032) -> 1605430.4 | M28: =MAX(M33:M1032) -> 1.0611622
K29: MIN | L29: =MIN(L33:L1032) -> -255302.69 | M29: =MIN(M33:M1032) -> 0.36887112
L31: NPV | M31: IRR
B32: YR | K32: REPLICATION | L32: =C39 -> 580981.53 | M32: =C40 -> 0.66336893
B33: 0 | C33: ='D.C.F'!C10 -> -2170200 | K33: 1 | L33: 350967.7 | M33: 0.58829591
B34: 1 | C34: =_xlfn.NORM.INV(RAND(),C$26,E$26) -> 1629596.5 | K34: 2 | L34: 619050.76 | M34: 0.68034721
B35: 2 | C35: =_xlfn.NORM.INV(RAND(),C$26,E$26) -> 2052558.4 | K35: 3 | L35: 174676.07 | M35: 0.52166796
B36: 3 | C36: =_xlfn.NORM.INV(RAND(),C$26,E$26) -> 2064777.4 | K36: 4 | L36: 206478.67 | M36: 0.53407273
K37: 5 | L37: 835809.19 | M37: 0.78570431
K38: 6 | L38: 174441.45 | M38: 0.51787094
B39: NPV | C39: =NPV(C28,C34:C36)+C33 -> 580981.53 | K39: 7 | L39: 677207.49 | M39: 0.72563355
B40: IRR | C40: =IRR(C33:C36) -> 0.66336893 | K40: 8 | L40: 573066.84 | M40: 0.6769806
K41: 9 | L41: 951550.64 | M41: 0.80049136
K42: 10 | L42: 613231.82 | M42: 0.70335807
K43: 11 | L43: 1023145.4 | M43: 0.86080552
K44: 12 | L44: 72746.529 | M44: 0.48480253
K45: 13 | L45: 762599.66 | M45: 0.74117999
K46: 14 | L46: 312149.14 | M46: 0.57926932
K47: 15 | L47: 544770.89 | M47: 0.64509579
K48: 16 | L48: 990536 | M48: 0.84753138
K49: 17 | L49: 646144.04 | M49: 0.71161038
K50: 18 | L50: 76551.7 | M50: 0.48486005
K51: 19 | L51: 676226.12 | M51: 0.70273244
K52: 20 | L52: 698981.76 | M52: 0.74096582
... K1032: 1000 | L1032: 896887.9 | M1032: 0.78984371

Sheet WACC
B2: WACC CALCULATOR
B4: COST OF EQ
B6: RISK FREE RATE | C6: 0.2484 | D6: Insert
B7: AVERAGE BETA | C7: 1.5 | D7: Insert
B8: EQ RISK PREMIUM | C8: 0.1394 | D8: Insert
B9: TOTAL COST OF EQ | C9: =C6+(C7*C8) -> 0.4575
B12: COST OF DEBT
B14: DEBT INTEREST RATE | C14: 0.195 | D14: Insert
B15: TAX RATE | C15: 0.225 | D15: Insert
B17: WACC
B19: COST OF EQUITY | C19: =C9 -> 0.4575
B20: EQ PROPORTION | C20: 1 | D20: Insert
B21: COST OF DEBT | C21: =C14 -> 0.195
B22: TAX SHIELD | C22: =1-C15 -> 0.775
B23: DEBT PROPORTION | C23: 0 | D23: Insert
B24: WACC | C24: =(C19*C20)+(C21*C22)*C23 -> 0.4575 | D24: Discount rate

Sheet B.E.P
B2: نقطة التعادل | C2: ='SCENARIO-1 '!D2 -> ABC
B4: سعر البيع
B6: عدد العماله | C6: ='SCENARIO-1 '!C36 -> 42
B7: أجمالي السعر | C7: ='SCENARIO-1 '!C176 -> 930000
B9: التكلفة المتغيرة
B11: رواتب | C11: ='SCENARIO-1 '!F36 -> 360000
B12: بدلات | C12: ='SCENARIO-1 '!G36 -> 0
B13: تأمينات | C13: ='SCENARIO-1 '!I36 -> 126386.54
B14: تأمين صحي | C14: ='SCENARIO-1 '!J36 -> 6370
B15: ضريبة كسب العمل | C15: ='SCENARIO-1 '!K36 -> 17885.135
B16: يونيفورم | C16: ='SCENARIO-1 '!L36 -> 4620
B17: ضريبة الشهداء | C17: ='SCENARIO-1 '!M36 -> 212.41435
B18: وجبات | C18: ='SCENARIO-1 '!E51 -> 0
B19: أجمالي | C19: =SUM(C11:C18) -> 515474.09
B20: تكلفة الفرد | C20: =C19/C6 -> 12273.193
B22: هامش المساهمة | C22: =C7-C19 -> 414525.91
B24: التكلفة الثابتة
B26: سكن | C26: ='SCENARIO-1 '!E57 -> 0
B27: أهلاك | C27: ='SCENARIO-1 '!G92 -> 60283.333
B28: صيانه | C28: ='SCENARIO-1 '!F98 -> 6028.3333
B29: مورد عماله | C29: ='SCENARIO-1 '!$G$45 -> 148800
B30: مستهلكات | C30: ='SCENARIO-1 '!C184 -> 16477.156
B31: مصاريف أدارية | C31: ='SCENARIO-1 '!C190 -> 35181.121
B32: ضرائب | C32: ='SCENARIO-1 '!C195 -> 41850
B33: أجمالي | C33: =SUM(C26:C32) -> 308619.94
B34: تكلفة الفرد | C34: =C33/C6 -> 7348.0939
B36: أجمالي التكاليف | C36: =C19+C33 -> 824094.03
B38: نسبة التكاليف المتغيرة | C38: =C19/C36 -> 0.62550397
B40: نسبة التكاليف الثابتة | C40: =C33/C36 -> 0.37449603
B42: نسبة هامش المساهمة | C42: =C22/C7 -> 0.44572679
B44: OPE.LEVERAGE | C44: =C22/C46 -> 3.914094 | D44: =C44 -> 3.914094
B46: صافي الدخل | C46: =C22-C33 -> 105905.97
C48: ='SCENARIO-1 '!C197 -> 105905.97
C49: =C46-C48 -> 0
B51: دخل التشغيل | C51: =C46+C32 -> 147755.97
C52: =C22/C51 -> 2.8054766
B57: رسم بياني
B59: عدد العماله | C59: =C6 -> 42
B61: التكلفة الثابتة | C61: =C33-C32 -> 266769.94
B62: التكلفة المتغيرة للفرد | C62: =C20 -> 12273.193
...

Sheet LEASE
B2: ايجار الأصول
C4: 1
C6: 1
B8: معدل الخصم | C8: 0.2
B9: معدل الخصم بعد الاعفاء الضريبي | C9: =C8*(1-22.5%) -> 0.155
B10: معدل العائد المطلوب | C10: 0.25
B11: الفترة | C11: =COUNT(B15:B17)*12 -> 36
B14: السنة | C14: الاهلاك
B15: 1 | C15: =-'P&L'!C11 -> 723400 | D15: =C15*CHOOSE($C$4,INPUTS!$D$28,INPUTS!$D$29) -> 162765 | E15: =-PV(CHOOSE($C$6,$C$8,$C$9),B15,D15) -> 135637.5
B16: 2 | C16: =-'P&L'!D11 -> 723400 | D16: =C16*CHOOSE($C$4,INPUTS!$D$28,INPUTS!$D$29) -> 162765 | E16: =-PV(CHOOSE($C$6,$C$8,$C$9),B16,D16) -> 248668.75
B17: 3 | C17: =-'P&L'!E11 -> 723400 | D17: =C17*CHOOSE($C$4,INPUTS!$D$28,INPUTS!$D$29) -> 162765 | E17: =-PV(CHOOSE($C$6,$C$8,$C$9),B17,D17) -> 342861.46
B18: الإجمالي | C18: =SUM(C15:C17) -> 2170200 | E18: =SUM(E15:E17) -> 727167.71
B20: صافي قيمة الأصول | C20: =C18-E18 -> 1443032.3
B21: قيمة القسط بعد الضرائب | C21: =-PMT(C10/12,C11,C20,,1) -> 56203.8 | D21: =C21*36 -> 2023336.8
B22: قيمة القسط قبل الضرائب | C22: =IFERROR(C21/CHOOSE($C$4,INPUTS!E28,INPUTS!D29),0) -> 72521.032
B24: سعر بيع الأصول | C24: =F.O!E26 -> 78837.099
B25: القيمة الحالية لسعر البيع | C25: =-PV($C$10/12,C11,C24,,1) -> 2024142.1 | D25: =C25/C18 -> 0.93269842
B27: قيمة الأصل في حالة التأجير التشغيلي | C27: =C18*0.8 -> 1736160
B28: قيمة القسط | C28: =-PMT($C$10/12,$C$11,C27,,1) -> 67620.656

Sheet LOANS
B2: Loan Schedule
B4: Number of periods | C4: 36 | D4: Insert
B5: Interest rate (annual) | C5: 0.2 | D5: Insert
B6: Interest rate (monthly) | C6: =C5/12 -> 0.016666667
B7: Loan Amount | C7: 0 | D7: Insert
B9: Monthly payment (EGP) | C9: =-PMT(C6,C4,C7) -> 0 | D9: =C9*12 -> 0 | E9: Year
C13: Period | D13: Payment | E13: Interest | F13: Principal | G13: Residual Debt
C14: 1 | D14: =$C$9 -> 0 | E14: =C7*C6 -> 0 | F14: =D14-E14 -> 0 | G14: =C7-F14 -> 0
C15: 2 | D15: =$C$9 -> 0 | E15: =G14*$C$6 -> 0 | F15: =D15-E15 -> 0 | G15: =G14-F15 -> 0
C16: 3 | D16: =$C$9 -> 0 | E16: =G15*$C$6 -> 0 | F16: =D16-E16 -> 0 | G16: =G15-F16 -> 0
C17: 4 | D17: =$C$9 -> 0 | E17: =G16*$C$6 -> 0 | F17: =D17-E17 -> 0 | G17: =G16-F17 -> 0
C18: 5 | D18: =$C$9 -> 0 | E18: =G17*$C$6 -> 0 | F18: =D18-E18 -> 0 | G18: =G17-F18 -> 0
C19: 6 | D19: =$C$9 -> 0 | E19: =G18*$C$6 -> 0 | F19: =D19-E19 -> 0 | G19: =G18-F19 -> 0
C20: 7 | D20: =$C$9 -> 0 | E20: =G19*$C$6 -> 0 | F20: =D20-E20 -> 0 | G20: =G19-F20 -> 0
C21: 8 | D21: =$C$9 -> 0 | E21: =G20*$C$6 -> 0 | F21: =D21-E21 -> 0 | G21: =G20-F21 -> 0
C22: 9 | D22: =$C$9 -> 0 | E22: =G21*$C$6 -> 0 | F22: =D22-E22 -> 0 | G22: =G21-F22 -> 0
C23: 10 | D23: =$C$9 -> 0 | E23: =G22*$C$6 -> 0 | F23: =D23-E23 -> 0 | G23: =G22-F23 -> 0
C24: 11 | D24: =$C$9 -> 0 | E24: =G23*$C$6 -> 0 | F24: =D24-E24 -> 0 | G24: =G23-F24 -> 0
C25: 12 | D25: =$C$9 -> 0 | E25: =G24*$C$6 -> 0 | F25: =D25-E25 -> 0 | G25: =G24-F25 -> 0
C26: 13 | D26: =$C$9 -> 0 | E26: =G25*$C$6 -> 0 | F26: =D26-E26 -> 0 | G26: =G25-F26 -> 0
... C133: 120 | D133: =$C$9 -> 0 | E133: =G132*$C$6 -> 0 | F133: =D133-E133 -> 0 | G133: =G132-F133 -> 0

Sheet G.SALARY
C2: عامل | D2: حاسبة رواتب Click
C4: تأمين بالراتب الأساسي | F4: تأمين بالحد الأدنى
C6: الوصف | D6: القيمة | F6: الوصف | G6: القيمة
C7: الراتب الإجمالي | D7: 8184.5238 | F7: الراتب الإجمالي | G7: 7580.8711
C8: الراتب التأميني | D8: =MAX(2700, MIN(D7, 16700)) -> 8184.5238 | F8: الراتب التأميني | G8: 2700
C9: نسبة الموظف من التأمينات | D9: =D8 * 0.11 -> 900.29762 | F9: نسبة الموظف من التأمينات | G9: =G8 * 0.11 -> 297
C10: الوعاء الضريبي | D10: =((D7 - D9) * 12 - 20000) / 12 -> 5617.5595 | F10: الوعاء الضريبي | G10: =((G7 - G9) * 12 - 20000) / 12 -> 5617.2044
C11: ضريبة كسب العمل | D11: {=_xlfn.IFS( (D10*12)<=600000, SUMPRODUCT(--((D10*12)>{0,40000,55000,70000,200000,400000,1200000}), ((D10*12)-{0,40000,55000,70000,200000,400000,1200000}), {0,0.1,0.05,0.05,0.025,0.025,0.025}), (D10*12)<=700000, SUMPRODUCT(--((D10*12)>{0,55000,70000,200000,400000,1200000}), ((D10*12)-{0,55000,70000,200000,400000,1200000}), {0.1,0.05,0.05,0.025,0.025,0.025}), (D10*12)<=800000, SUMPRODUCT(--((D10*12)>{0,70000,200000,400000,1200000}), ((D10*12)-{0,70000,200000,400000,1200000}), {0.15,0.05,0.025,0.025,0.025}), (D10*12)<=900000, SUMPRODUCT(--((D10*12)>{0,200000,400000,1200000}), ((D10*12)-{0,200000,400000,1200000}), {0.2,0.025,0.025,0.025}), (D10*12)<=1200000, SUMPRODUCT(--((D10*12)>{0,400000,1200000}), ((D10*12)-{0,400000,1200000}), {0.225,0.025,0.025}), (D10*12)>1200000, SUMPRODUCT(--((D10*12)>{0,1200000}), ((D10*12)-{0,1200000}), {0.25,0.025}) ) / 12} -> 280.13393 | F11: ضريبة كسب العمل | G11: {=_xlfn.IFS( (G10*12)<=600000, SUMPRODUCT(--((G10*12)>{0,40000,55000,70000,200000,400000,1200000}), ((G10*12)-{0,40000,55000,70000,200000,400000,1200000}), {0,0.1,0.05,0.05,0.025,0.025,0.025}), (G10*12)<=700000, SUMPRODUCT(--((G10*12)>{0,55000,70000,200000,400000,1200000}), ((G10*12)-{0,55000,70000,200000,400000,1200000}), {0.1,0.05,0.05,0.025,0.025,0.025}), (G10*12)<=800000, SUMPRODUCT(--((G10*12)>{0,70000,200000,400000,1200000}), ((G10*12)-{0,70000,200000,400000,1200000}), {0.15,0.05,0.025,0.025,0.025}), (G10*12)<=900000, SUMPRODUCT(--((G10*12)>{0,200000,400000,1200000}), ((G10*12)-{0,200000,400000,1200000}), {0.2,0.025,0.025,0.025}), (G10*12)<=1200000, SUMPRODUCT(--((G10*12)>{0,400000,1200000}), ((G10*12)-{0,400000,1200000}), {0.225,0.025,0.025}), (G10*12)>1200000, SUMPRODUCT(--((G10*12)>{0,1200000}), ((G10*12)-{0,1200000}), {0.25,0.025}) ) / 12} -> 280.08067
C12: صندوق الشهداء | D12: =D7 * 0.0005 -> 4.0922619 | F12: صندوق الشهداء | G12: =G7 * 0.0005 -> 3.7904356
C13: صافي الراتب | D13: =D7-D9-D11-D12 -> 7000 | F13: صافي الراتب | G13: =G7-G9-G11-G12 -> 7000
C16: نسبة الشركة من التأمينات | D16: =D8*(18.75%) -> 1534.5982 | F16: نسبة الشركة من التأمينات | G16: =G8*(18.75%) -> 506.25
C17: تأمين صحي شامل | D17: 130 | F17: تأمين صحي شامل | G17: 130
C18: أجمالي تكلفة العامل على الشركة | D18: =D7+D16+D17 -> 9849.122 | F18: أجمالي تكلفة العامل على الشركة | G18: =G7+G16+G17 -> 8217.1211
C21: مشرف
C23: تأمين بالراتب الأساسي | F23: تأمين بالحد الأدنى
C25: الوصف | D25: القيمة | F25: الوصف | G25: القيمة
C26: الراتب الإجمالي | D26: 10980.323 | F26: الراتب الإجمالي | G26: 10068.918
C27: الراتب التأميني | D27: =MAX(2700, MIN(D26, 16700)) -> 10980.323 | F27: الراتب التأميني | G27: 2700
C28: نسبة الموظف من التأمينات | D28: =D27 * 0.11 -> 1207.8356 | F28: نسبة الموظف من التأمينات | G28: =G27 * 0.11 -> 297
C29: الوعاء الضريبي | D29: =((D26 - D28) * 12 - 20000) / 12 -> 8105.821 | F29: الوعاء الضريبي | G29: =((G26 - G28) * 12 - 20000) / 12 -> 8105.2514
C30: ضريبة كسب العمل | D30: {=_xlfn.IFS( (D29*12)<=600000, SUMPRODUCT(--((D29*12)>{0,40000,55000,70000,200000,400000,1200000}), ((D29*12)-{0,40000,55000,70000,200000,400000,1200000}), {0,0.1,0.05,0.05,0.025,0.025,0.025}), (D29*12)<=700000, SUMPRODUCT(--((D29*12)>{0,55000,70000,200000,400000,1200000}), ((D29*12)-{0,55000,70000,200000,400000,1200000}), {0.1,0.05,0.05,0.025,0.025,0.025}), (D29*12)<=800000, SUMPRODUCT(--((D29*12)>{0,70000,200000,400000,1200000}), ((D29*12)-{0,70000,200000,400000,1200000}), {0.15,0.05,0.025,0.025,0.025}), (D29*12)<=900000, SUMPRODUCT(--((D29*12)>{0,200000,400000,1200000}), ((D29*12)-{0,200000,400000,1200000}), {0.2,0.025,0.025,0.025}), (D29*12)<=1200000, SUMPRODUCT(--((D29*12)>{0,400000,1200000}), ((D29*12)-{0,400000,1200000}), {0.225,0.025,0.025}), (D29*12)>1200000, SUMPRODUCT(--((D29*12)>{0,1200000}), ((D29*12)-{0,1200000}), {0.25,0.025}) ) / 12} -> 766.99754 | F30: ضريبة كسب العمل | G30: {=_xlfn.IFS( (G29*12)<=600000, SUMPRODUCT(--((G29*12)>{0,40000,55000,70000,200000,400000,1200000}), ((G29*12)-{0,40000,55000,70000,200000,400000,1200000}), {0,0.1,0.05,0.05,0.025,0.025,0.025}), (G29*12)<=700000, SUMPRODUCT(--((G29*12)>{0,55000,70000,200000,400000,1200000}), ((G29*12)-{0,55000,70000,200000,400000,1200000}), {0.1,0.05,0.05,0.025,0.025,0.025}), (G29*12)<=800000, SUMPRODUCT(--((G29*12)>{0,70000,200000,400000,1200000}), ((G29*12)-{0,70000,200000,400000,1200000}), {0.15,0.05,0.025,0.025,0.025}), (G29*12)<=900000, SUMPRODUCT(--((G29*12)>{0,200000,400000,1200000}), ((G29*12)-{0,200000,400000,1200000}), {0.2,0.025,0.025,0.025}), (G29*12)<=1200000, SUMPRODUCT(--((G29*12)>{0,400000,1200000}), ((G29*12)-{0,400000,1200000}), {0.225,0.025,0.025}), (G29*12)>1200000, SUMPRODUCT(--((G29*12)>{0,1200000}), ((G29*12)-{0,1200000}), {0.25,0.025}) ) / 12} -> 766.88361
C31: صندوق الشهداء | D31: =D26 * 0.0005 -> 5.4901616 | F31: صندوق الشهداء | G31: =G26 * 0.0005 -> 5.034459
C32: صافي الراتب | D32: =D26-D28-D30-D31 -> 9000 | F32: صافي الراتب | G32: =G26-G28-G30-G31 -> 9000
C35: نسبة الشركة من التأمينات | D35: =D27*(18.75%) -> 2058.8106 | F35: نسبة الشركة من التأمينات | G35: =G27*(18.75%) -> 506.25
C36: تأمين صحي شامل | D36: 130 | F36: تأمين صحي شامل | G36: 130
C37: أجمالي تكلفة العامل على الشركة | D37: =D26+D35+D36 -> 13169.134 | F37: أجمالي تكلفة العامل على الشركة | G37: =G26+G35+G36 -> 10705.168
C40: مدير
C42: تأمين بالراتب الأساسي | F42: تأمين بالحد الأدنى
C44: الوصف | D44: القيمة | F44: الوصف | G44: القيمة
C45: الراتب الإجمالي | D45: 15196.767 | F45: الراتب الإجمالي | G45: 13821.263
C46: الراتب التأميني | D46: =MAX(2700, MIN(D45, 16700)) -> 15196.767 | F46: الراتب التأميني | G46: 2700
C47: نسبة الموظف من التأمينات | D47: =D46 * 0.11 -> 1671.6444 | F47: نسبة الموظف من التأمينات | G47: =G46 * 0.11 -> 297
C48: الوعاء الضريبي | D48: =((D45 - D47) * 12 - 20000) / 12 -> 11858.456 | F48: الوعاء الضريبي | G48: =((G45 - G47) * 12 - 20000) / 12 -> 11857.597
C49: ضريبة كسب العمل | D49: {=_xlfn.IFS( (D48*12)<=600000, SUMPRODUCT(--((D48*12)>{0,40000,55000,70000,200000,400000,1200000}), ((D48*12)-{0,40000,55000,70000,200000,400000,1200000}), {0,0.1,0.05,0.05,0.025,0.025,0.025}), (D48*12)<=700000, SUMPRODUCT(--((D48*12)>{0,55000,70000,200000,400000,1200000}), ((D48*12)-{0,55000,70000,200000,400000,1200000}), {0.1,0.05,0.05,0.025,0.025,0.025}), (D48*12)<=800000, SUMPRODUCT(--((D48*12)>{0,70000,200000,400000,1200000}), ((D48*12)-{0,70000,200000,400000,1200000}), {0.15,0.05,0.025,0.025,0.025}), (D48*12)<=900000, SUMPRODUCT(--((D48*12)>{0,200000,400000,1200000}), ((D48*12)-{0,200000,400000,1200000}), {0.2,0.025,0.025,0.025}), (D48*12)<=1200000, SUMPRODUCT(--((D48*12)>{0,400000,1200000}), ((D48*12)-{0,400000,1200000}), {0.225,0.025,0.025}), (D48*12)>1200000, SUMPRODUCT(--((D48*12)>{0,1200000}), ((D48*12)-{0,1200000}), {0.25,0.025}) ) / 12} -> 1517.5246 | F49: ضريبة كسب العمل | G49: {=_xlfn.IFS( (G48*12)<=600000, SUMPRODUCT(--((G48*12)>{0,40000,55000,70000,200000,400000,1200000}), ((G48*12)-{0,40000,55000,70000,200000,400000,1200000}), {0,0.1,0.05,0.05,0.025,0.025,0.025}), (G48*12)<=700000, SUMPRODUCT(--((G48*12)>{0,55000,70000,200000,400000,1200000}), ((G48*12)-{0,55000,70000,200000,400000,1200000}), {0.1,0.05,0.05,0.025,0.025,0.025}), (G48*12)<=800000, SUMPRODUCT(--((G48*12)>{0,70000,200000,400000,1200000}), ((G48*12)-{0,70000,200000,400000,1200000}), {0.15,0.05,0.025,0.025,0.025}), (G48*12)<=900000, SUMPRODUCT(--((G48*12)>{0,200000,400000,1200000}), ((G48*12)-{0,200000,400000,1200000}), {0.2,0.025,0.025,0.025}), (G48*12)<=1200000, SUMPRODUCT(--((G48*12)>{0,400000,1200000}), ((G48*12)-{0,400000,1200000}), {0.225,0.025,0.025}), (G48*12)>1200000, SUMPRODUCT(--((G48*12)>{0,1200000}), ((G48*12)-{0,1200000}), {0.25,0.025}) ) / 12} -> 1517.3527
C50: صندوق الشهداء | D50: =D45 * 0.0005 -> 7.5983837 | F50: صندوق الشهداء | G50: =G45 * 0.0005 -> 6.9106316
C51: صافي الراتب | D51: =D45-D47-D49-D50 -> 12000 | F51: صافي الراتب | G51: =G45-G47-G49-G50 -> 12000
C54: نسبة الشركة من التأمينات | D54: =D46*(18.75%) -> 2849.3939 | F54: نسبة الشركة من التأمينات | G54: =G46*(18.75%) -> 506.25
C55: تأمين صحي شامل | D55: 130 | F55: تأمين صحي شامل | G55: 130
C56: أجمالي تكلفة العامل على الشركة | D56: =D45+D54+D55 -> 18176.161 | F56: أجمالي تكلفة العامل على الشركة | G56: =G45+G54+G55 -> 14457.513

Sheet INPUTS
B2: مدخلات
B4: تكلفة العمالة
C5: 1
C6: 2
B8: عدد العمالة
C9: 1 | D9: =8*30 -> 240 | E9: اختيار1: 8 ساعات/7 أيام
C10: 2 | D10: =8*26 -> 208 | E10: اختيار2: 8 ساعات/6 أيام
C11: 3 | D11: =12*30 -> 360 | E11: اختيار3: 12 ساعة/7 أيام
C12: 4 | D12: =12*26 -> 312 | E12: اختيار4: 12 ساعة/6 أيام
B14: اجمالي العمالة
C15: 1
C16: 2
C17: 3
B18: تكلفة مورد الافراد
C19: 1 | D19: 31
C20: 2 | D20: 27
B22: مصاريف إدارية
C23: 1
C24: 2
B26: ايجار المعدات
C28: 1 | D28: 0.225 | E28: =1-22.5% -> 0.775
C29: 2 | D29: 0
